Workbook

Sheet Raw_Data
A1: RespondentID | B1: Timestamp | C1: A1 | D1: A2 | E1: A3 | F1: A4 | G1: A5 | H1: A6 | I1: A7 | J1: A8 | K1: F1a | L1: F1b | M1: F1c | N1: F1d | O1: F1e | P1: F1f | Q1: F2a | R1: F2b | S1: F2c | T1: F2d | U1: F2e | V1: F3a | W1: F3b | X1: F3c | Y1: F3d | Z1: F4a | AA1: F4b | AB1: F4c | AC1: F4d | AD1: F4e | AE1: F4f | AF1: F4g | AG1: F5a | AH1: F5b | AI1: F5c | AJ1: F5d | AK1: F5e | AL1: F6a | AM1: F6b | AN1: F6c | AO1: F6d | AP1: F7a | AQ1: F7b | AR1: F7c | AS1: F7d | AT1: C1 | AU1: C2 | AV1: C3 | AW1: C4 | AX1: C5 | AY1: C6 | AZ1: D1 | BA1: D2 | BB1: D3 | BC1: D4 | BD1: D5 | BE1: D6 | BF1: D7 | BG1: D8 | BH1: Uses_LMS | BI1: Uses_SMIS | BJ1: Uses_AI_Teaching | BK1: Uses_AI_Admin | BL1: Uses_VideoConf | BM1: Uses_DigitalLibrary | BN1: Uses_None
A2: 1 | B2: 7/27/2026 13:23:35 | C2: Headteacher / Principal | D2: Senior High School (SHS) | E2: Greater Accra | F2: Public / Government | G2: 1,000 – 4,999 | H2: 50 – 99 | I2: Yes, with dedicated full-time staff | J2: 4 – 7 years | K2: 5 | L2: 5 | M2: 4 | N2: 4 | O2: 5 | P2: 1 | Q2: 4 | R2: 3 | S2: 4 | T2: 4 | U2: 2 | V2: 4 | W2: 5 | X2: 3 | Y2: 2 | Z2: 4 | AA2: 4 | AB2: 3 | AC2: 3 | AD2: 4 | AE2: 3 | AF2: 2 | AG2: 4 | AH2: 5 | AI2: 4 | AJ2: 3 | AK2: 2 | AL2: 4 | AM2: 4 | AN2: 4 | AO2: 2 | AP2: 3 | AQ2: 2 | AR2: 4 | AS2: 3 | AT2: Learning Management System (LMS) — e.g., Moodle, Google Classroom, School Management Information System (SMIS), AI-powered tools for teaching or assessment (e.g., ChatGPT, Grammarly, adaptive tutoring systems), Video conferencing or online learning platforms, Digital library or e-resource system | AU2: Exploring — we are evaluating or piloting specific AI tools | AV2: Insufficient financial resources | AW2: Staff training and professional development | AX2: 7 | AZ2: More than 50 years | BA2: I have personally tried one or more AI tools for education | BB2: Some — infrastructure improvement (e.g., internet, devices) through a government programme | BC2: I am aware of it and have read parts of it | BD2: All of the above — a comprehensive national AI-in-education strategy is needed | BE2: A relationship with a university or research institution | BF2: AI will be integrated into several teaching and administrative functions | BG2: The widening gap between well-resourced and under-resourced institutions | BH2: 1 | BI2: 1 | BJ2: 1 | BK2: 0 | BL2: 1 | BM2: 1 | BN2: 0
A3: 2 | B3: 7/27/2026 13:40:26 | C3: Other | D3: Senior High School (SHS) | E3: Greater Accra | F3: Public / Government | G3: 1,000 – 4,999 | H3: 50 – 99 | I3: Yes, but staffed part-time or informally | J3: 4 – 7 years | K3: 5 | L3: 5 | M3: 4 | N3: 4 | O3: 5 | P3: 4 | Q3: 3 | R3: 4 | S3: 4 | T3: 2 | U3: 4 | V3: 5 | W3: 3 | X3: 5 | Y3: 4 | Z3: 5 | AA3: 3 | AB3: 2 | AC3: 4 | AD3: 4 | AE3: 3 | AF3: 3 | AG3: 4 | AH3: 3 | AI3: 2 | AJ3: 4 | AK3: 5 | AL3: 4 | AM3: 3 | AN3: 4 | AO3: 4 | AP3: 4 | AQ3: 2 | AR3: 5 | AS3: 4 | AT3: Learning Management System (LMS) — e.g., Moodle, Google Classroom | AU3: Exploring — we are evaluating or piloting specific AI tools | AV3: Insufficient financial resources | AW3: Staff training and professional development | AX3: 7 | AZ3: More than 50 years | BA3: I have no knowledge of what AI tools for education are | BB3: Some — infrastructure improvement (e.g., internet, devices) through a government programme | BC3: I am aware of it and have read parts of it | BD3: All of the above — a comprehensive national AI-in-education strategy is needed | BE3: Support from an NGO or international development organisation | BF3: AI will be integrated into several teaching and administrative functions | BG3: The widening gap between well-resourced and under-resourced institutions | BH3: 1 | BI3: 0 | BJ3: 0 | BK3: 0 | BL3: 0 | BM3: 0 | BN3: 0
A4: 3 | B4: 7/27/2026 13:57:02 | C4: Staff | D4: Senior High School (SHS) | E4: Greater Accra | F4: Public / Government | G4: 1,000 – 4,999 | H4: 50 – 99 | I4: Yes, with dedicated full-time staff | J4: 4 – 7 years | K4: 5 | L4: 5 | M4: 4 | N4: 4 | O4: 5 | P4: 1 | Q4: 4 | R4: 3 | S4: 4 | T4: 4 | U4: 2 | V4: 4 | W4: 5 | X4: 3 | Y4: 2 | Z4: 4 | AA4: 4 | AB4: 3 | AC4: 3 | AD4: 4 | AE4: 3 | AF4: 2 | AG4: 4 | AH4: 5 | AI4: 4 | AJ4: 3 | AK4: 2 | AL4: 4 | AM4: 4 | AN4: 4 | AO4: 2 | AP4: 3 | AQ4: 2 | AR4: 3 | AS4: 4 | AT4: Learning Management System (LMS) — e.g., Moodle, Google Classroom, School Management Information System (SMIS), AI-powered tools for teaching or assessment (e.g., ChatGPT, Grammarly, adaptive tutoring systems), AI-powered administrative tools (e.g., automated timetabling, attendance tracking), Video conferencing or online learning platforms, Digital library or e-resource system | AU4: Exploring — we are evaluating or piloting specific AI tools | AV4: Insufficient financial resources | AW4: Staff training and professional development | AX4: 7 | AZ4: More than 50 years | BA4: I have personally tried one or more AI tools for education | BB4: Some — infrastructure improvement (e.g., internet, devices) through a government programme | BC4: I am aware of it and have read parts of it | BD4: All of the above — a comprehensive national AI-in-education strategy is needed | BE4: Support from an NGO or international development organisation | BF4: AI will be integrated into several teaching and administrative functions | BG4: The widening gap between well-resourced and under-resourced institutions | BH4: 1 | BI4: 1 | BJ4: 1 | BK4: 1 | BL4: 1 | BM4: 1 | BN4: 0
A5: 4 | B5: 7/27/2026 13:57:27 | C5: Staff | D5: Senior High School (SHS) | E5: Greater Accra | F5: Public / Government | G5: 1,000 – 4,999 | H5: 50 – 99 | I5: Yes, with dedicated full-time staff | J5: 4 – 7 years | K5: 5 | L5: 5 | M5: 4 | N5: 4 | O5: 5 | P5: 1 | Q5: 4 | R5: 3 | S5: 4 | T5: 4 | U5: 2 | V5: 4 | W5: 5 | X5: 3 | Y5: 2 | Z5: 4 | AA5: 4 | AB5: 3 | AC5: 3 | AD5: 4 | AE5: 3 | AF5: 2 | AG5: 4 | AH5: 5 | AI5: 4 | AJ5: 3 | AK5: 2 | AL5: 4 | AM5: 4 | AN5: 4 | AO5: 2 | AP5: 3 | AQ5: 2 | AR5: 3 | AS5: 4 | AT5: Learning Management System (LMS) — e.g., Moodle, Google Classroom, School Management Information System (SMIS), AI-powered tools for teaching or assessment (e.g., ChatGPT, Grammarly, adaptive tutoring systems), AI-powered administrative tools (e.g., automated timetabling, attendance tracking), Video conferencing or online learning platforms, Digital library or e-resource system | AU5: Exploring — we are evaluating or piloting specific AI tools | AV5: Insufficient financial resources | AW5: Staff training and professional development | AX5: 7 | AZ5: More than 50 years | BA5: I have personally tried one or more AI tools for education | BB5: Some — infrastructure improvement (e.g., internet, devices) through a government programme | BC5: I am aware of it and have read parts of it | BD5: All of the above — a comprehensive national AI-in-education strategy is needed | BE5: Support from an NGO or international development organisation | BF5: AI will be integrated into several teaching and administrative functions | BG5: The widening gap between well-resourced and under-resourced institutions | BH5: 1 | BI5: 1 | BJ5: 1 | BK5: 1 | BL5: 1 | BM5: 1 | BN5: 0
A6: 5 | B6: 7/27/2026 14:03:44 | C6: Staff | D6: Senior High School (SHS) | E6: Greater Accra | F6: Public / Government | G6: 1,000 – 4,999 | H6: 50 – 99 | I6: Yes, with dedicated full-time staff | J6: 4 – 7 years | K6: 5 | L6: 5 | M6: 4 | N6: 4 | O6: 5 | P6: 1 | Q6: 4 | R6: 3 | S6: 4 | T6: 4 | U6: 2 | V6: 4 | W6: 5 | X6: 3 | Y6: 2 | Z6: 4 | AA6: 4 | AB6: 3 | AC6: 3 | AD6: 4 | AE6: 3 | AF6: 2 | AG6: 4 | AH6: 5 | AI6: 4 | AJ6: 3 | AK6: 2 | AL6: 4 | AM6: 4 | AN6: 4 | AO6: 2 | AP6: 3 | AQ6: 2 | AR6: 3 | AS6: 4 | AT6: Learning Management System (LMS) — e.g., Moodle, Google Classroom, School Management Information System (SMIS), AI-powered tools for teaching or assessment (e.g., ChatGPT, Grammarly, adaptive tutoring systems), AI-powered administrative tools (e.g., automated timetabling, attendance tracking), Video conferencing or online learning platforms, Digital library or e-resource system | AU6: Exploring — we are evaluating or piloting specific AI tools | AV6: Insufficient financial resources | AW6: Staff training and professional development | AX6: 7 | AZ6: More than 50 years | BA6: I have personally tried one or more AI tools for education | BB6: Some — infrastructure improvement (e.g., internet, devices) through a government programme | BC6: I am aware of it and have read parts of it | BD6: All of the above — a comprehensive national AI-in-education strategy is needed | BE6: Support from an NGO or international development organisation | BF6: AI will be integrated into several teaching and administrative functions | BG6: The widening gap between well-resourced and under-resourced institutions | BH6: 1 | BI6: 1 | BJ6: 1 | BK6: 1 | BL6: 1 | BM6: 1 | BN6: 0
A7: 6 | B7: 7/27/2026 14:03:51 | C7: Staff | D7: Senior High School (SHS) | E7: Greater Accra | F7: Public / Government | G7: 1,000 – 4,999 | H7: 50 – 99 | I7: Yes, with dedicated full-time staff | J7: 4 – 7 years | K7: 5 | L7: 5 | M7: 4 | N7: 4 | O7: 5 | P7: 1 | Q7: 4 | R7: 3 | S7: 4 | T7: 4 | U7: 2 | V7: 4 | W7: 5 | X7: 3 | Y7: 2 | Z7: 4 | AA7: 4 | AB7: 3 | AC7: 3 | AD7: 4 | AE7: 3 | AF7: 2 | AG7: 4 | AH7: 5 | AI7: 4 | AJ7: 3 | AK7: 2 | AL7: 4 | AM7: 4 | AN7: 4 | AO7: 2 | AP7: 3 | AQ7: 2 | AR7: 3 | AS7: 4 | AT7: Learning Management System (LMS) — e.g., Moodle, Google Classroom, School Management Information System (SMIS), AI-powered tools for teaching or assessment (e.g., ChatGPT, Grammarly, adaptive tutoring systems), AI-powered administrative tools (e.g., automated timetabling, attendance tracking), Video conferencing or online learning platforms, Digital library or e-resource system | AU7: Exploring — we are evaluating or piloting specific AI tools | AV7: Insufficient financial resources | AW7: Staff training and professional development | AX7: 7 | AZ7: More than 50 years | BA7: I have personally tried one or more AI tools for education | BB7: Some — infrastructure improvement (e.g., internet, devices) through a government programme | BC7: I am aware of it and have read parts of it | BD7: All of the above — a comprehensive national AI-in-education strategy is needed | BE7: Support from an NGO or international development organisation | BF7: AI will be integrated into several teaching and administrative functions | BG7: The widening gap between well-resourced and under-resourced institutions | BH7: 1 | BI7: 1 | BJ7: 1 | BK7: 1 | BL7: 1 | BM7: 1 | BN7: 0
A8: 7 | B8: 7/27/2026 14:06:12 | C8: Staff | D8: Senior High School (SHS) | E8: Greater Accra | F8: Public / Government | G8: 1,000 – 4,999 | H8: 50 – 99 | I8: Yes, with dedicated full-time staff | J8: More than 15 years | K8: 5 | L8: 4 | M8: 4 | N8: 5 | O8: 4 | P8: 4 | Q8: 4 | R8: 5 | S8: 5 | T8: 5 | U8: 3 | V8: 4 | W8: 4 | X8: 4 | Y8: 3 | Z8: 5 | AA8: 4 | AB8: 4 | AC8: 3 | AD8: 3 | AE8: 4 | AF8: 4 | AG8: 4 | AH8: 5 | AI8: 5 | AJ8: 5 | AK8: 4 | AL8: 4 | AM8: 5 | AN8: 5 | AO8: 4 | AP8: 5 | AQ8: 4 | AR8: 5 | AS8: 5 | AT8: AI-powered tools for teaching or assessment (e.g., ChatGPT, Grammarly, adaptive tutoring systems) | AU8: Exploring — we are evaluating or piloting specific AI tools | AV8: Insufficient financial resources | AW8: Staff training and professional development | AX8: 7 | AZ8: More than 50 years | BA8: I am aware of AI tools (e.g., ChatGPT, adaptive learning platforms) but have not used them | BB8: Some — infrastructure improvement (e.g., internet, devices) through a government programme | BC8: I am familiar with it but it has had no practical impact at my institution | BD8: All of the above — a comprehensive national AI-in-education strategy is needed | BE8: Support from an NGO or international development organisation | BF8: AI will be integrated into several teaching and administrative functions | BG8: The widening gap between well-resourced and under-resourced institutions | BH8: 0 | BI8: 0 | BJ8: 1 | BK8: 0 | BL8: 0 | BM8: 0 | BN8: 0
A9: 8 | B9: 7/27/2026 14:25:03 | C9: Staff | D9: Senior High School (SHS) | E9: Greater Accra | F9: Public / Government | G9: 1,000 – 4,999 | H9: 20 – 49 | I9: Yes, but staffed part-time or informally | J9: More than 15 years | K9: 4 | L9: 3 | M9: 3 | N9: 3 | O9: 4 | P9: 5 | Q9: 5 | R9: 5 | S9: 4 | T9: 4 | U9: 4 | V9: 3 | W9: 2 | X9: 5 | Y9: 5 | Z9: 4 | AA9: 4 | AB9: 4 | AC9: 4 | AD9: 3 | AE9: 5 | AF9: 3 | AG9: 2 | AH9: 4 | AI9: 3 | AJ9: 5 | AK9: 5 | AL9: 5 | AM9: 4 | AN9: 4 | AO9: 5 | AP9: 5 | AQ9: 4 | AR9: 4 | AS9: 4 | AT9: AI-powered administrative tools (e.g., automated timetabling, attendance tracking) | AU9: Exploring — we are evaluating or piloting specific AI tools | AV9: Insufficient financial resources | AW9: Staff training and professional development | AX9: 8 | AZ9: More than 50 years | BA9: I am aware of AI tools (e.g., ChatGPT, adaptive learning platforms) but have not used them | BB9: Some — infrastructure improvement (e.g., internet, devices) through a government programme | BC9: I am aware of it and have read parts of it | BD9: All of the above — a comprehensive national AI-in-education strategy is needed | BE9: Support from an NGO or international development organisation | BF9: AI will be integrated into several teaching and administrative functions | BG9: The absence of data privacy frameworks and ethical guidelines | BH9: 0 | BI9: 0 | BJ9: 0 | BK9: 1 | BL9: 0 | BM9: 0 | BN9: 0
A10: 9 | B10: 7/27/2026 14:31:32 | C10: Other | D10: Senior High School (SHS) | E10: Greater Accra | F10: Public / Government | G10: 1,000 – 4,999 | H10: 50 – 99 | I10: Yes, with dedicated full-time staff | J10: 8 – 15 years | K10: 4 | L10: 4 | M10: 5 | N10: 5 | O10: 3 | P10: 4 | Q10: 5 | R10: 3 | S10: 3 | T10: 4 | U10: 2 | V10: 4 | W10: 4 | X10: 4 | Y10: 5 | Z10: 4 | AA10: 4 | AB10: 4 | AC10: 4 | AD10: 3 | AE10: 2 | AF10: 2 | AG10: 3 | AH10: 2 | AI10: 4 | AJ10: 4 | AK10: 2 | AL10: 3 | AM10: 5 | AN10: 5 | AO10: 5 | AP10: 5 | AQ10: 5 | AR10: 4 | AS10: 4 | AT10: AI-powered tools for teaching or assessment (e.g., ChatGPT, Grammarly, adaptive tutoring systems) | AU10: Exploring — we are evaluating or piloting specific AI tools | AV10: Insufficient financial resources | AW10: Staff training and professional development | AX10: 9 | AZ10: More than 50 years | BA10: I am aware of AI tools (e.g., ChatGPT, adaptive learning platforms) but have not used them | BB10: Yes — meaningful support from an NGO, private company, or international organisation | BC10: I am aware of it and have read parts of it | BD10: All of the above — a comprehensive national AI-in-education strategy is needed | BE10: Support from an NGO or international development organisation | BF10: AI will be integrated into several teaching and administrative functions | BG10: The widening gap between well-resourced and under-resourced institutions | BH10: 0 | BI10: 0 | BJ10: 1 | BK10: 0 | BL10: 0 | BM10: 0 | BN10: 0
A11: 10 | B11: 7/27/2026 14:34:58 | C11: Other | D11: Senior High School (SHS) | E11: Greater Accra | F11: Public / Government | G11: 1,000 – 4,999 | H11: 50 – 99 | I11: Yes, with dedicated full-time staff | J11: 8 – 15 years | K11: 5 | L11: 5 | M11: 4 | N11: 4 | O11: 4 | P11: 3 | Q11: 4 | R11: 4 | S11: 4 | T11: 4 | U11: 3 | V11: 3 | W11: 4 | X11: 3 | Y11: 4 | Z11: 5 | AA11: 4 | AB11: 3 | AC11: 4 | AD11: 2 | AE11: 2 | AF11: 5 | AG11: 4 | AH11: 4 | AI11: 4 | AJ11: 5 | AK11: 5 | AL11: 4 | AM11: 5 | AN11: 5 | AO11: 4 | AP11: 3 | AQ11: 3 | AR11: 1 | AS11: 4 | AT11: AI-powered tools for teaching or assessment (e.g., ChatGPT, Grammarly, adaptive tutoring systems) | AU11: Exploring — we are evaluating or piloting specific AI tools | AV11: Insufficient financial resources | AW11: Staff training and professional development | AX11: 7 | AZ11: More than 50 years | BA11: I am aware of AI tools (e.g., ChatGPT, adaptive learning platforms) but have not used them | BB11: Yes — ongoing partnership with consistent technology support | BC11: I am familiar with it but it has had no practical impact at my institution | BD11: All of the above — a comprehensive national AI-in-education strategy is needed | BE11: Support from an NGO or international development organisation | BF11: AI will be integrated into several teaching and administrative functions | BG11: The widening gap between well-resourced and under-resourced institutions | BH11: 0 | BI11: 0 | BJ11: 1 | BK11: 0 | BL11: 0 | BM11: 0 | BN11: 0
A12: 11 | B12: 7/27/2026 14:40:28 | C12: Staff | D12: Senior High School (SHS) | E12: Greater Accra | F12: Public / Government | G12: 1,000 – 4,999 | H12: 50 – 99 | I12: Yes, with dedicated full-time staff | J12: More than 15 years | K12: 3 | L12: 4 | M12: 5 | N12: 4 | O12: 3 | P12: 5 | Q12: 4 | R12: 3 | S12: 5 | T12: 5 | U12: 5 | V12: 3 | W12: 3 | X12: 2 | Y12: 3 | Z12: 5 | AA12: 5 | AB12: 5 | AC12: 5 | AD12: 3 | AE12: 3 | AF12: 4 | AG12: 3 | AH12: 4 | AI12: 3 | AJ12: 5 | AK12: 5 | AL12: 5 | AM12: 5 | AN12: 4 | AO12: 2 | AP12: 3 | AQ12: 2 | AR12: 4 | AS12: 4 | AT12: AI-powered tools for teaching or assessment (e.g., ChatGPT, Grammarly, adaptive tutoring systems) | AU12: Exploring — we are evaluating or piloting specific AI tools | AV12: Insufficient financial resources | AW12: Staff training and professional development | AX12: 9 | AZ12: More than 50 years | BA12: I am aware of AI tools (e.g., ChatGPT, adaptive learning platforms) but have not used them | BB12: Yes — meaningful support from an NGO, private company, or international organisation | BC12: I am aware of it and have read parts of it | BD12: All of the above — a comprehensive national AI-in-education strategy is needed | BE12: Support from an NGO or international development organisation | BF12: AI will be integrated into several teaching and administrative functions | BG12: The widening gap between well-resourced and under-resourced institutions | BH12: 0 | BI12: 0 | BJ12: 1 | BK12: 0 | BL12: 0 | BM12: 0 | BN12: 0
A13: 12 | B13: 7/27/2026 14:52:54 | C13: Staff | D13: Senior High School (SHS) | E13: Greater Accra | F13: Public / Government | G13: 1,000 – 4,999 | H13: 50 – 99 | I13: Yes, with dedicated full-time staff | J13: 4 – 7 years | K13: 5 | L13: 5 | M13: 4 | N13: 4 | O13: 5 | P13: 1 | Q13: 4 | R13: 3 | S13: 4 | T13: 4 | U13: 2 | V13: 4 | W13: 5 | X13: 3 | Y13: 2 | Z13: 4 | AA13: 4 | AB13: 3 | AC13: 3 | AD13: 4 | AE13: 3 | AF13: 2 | AG13: 4 | AH13: 5 | AI13: 4 | AJ13: 3 | AK13: 2 | AL13: 4 | AM13: 4 | AN13: 4 | AO13: 2 | AP13: 3 | AQ13: 2 | AR13: 3 | AS13: 4 | AT13: Learning Management System (LMS) — e.g., Moodle, Google Classroom, School Management Information System (SMIS), AI-powered tools for teaching or assessment (e.g., ChatGPT, Grammarly, adaptive tutoring systems), AI-powered administrative tools (e.g., automated timetabling, attendance tracking), Video conferencing or online learning platforms, Digital library or e-resource system | AU13: Exploring — we are evaluating or piloting specific AI tools | AV13: Insufficient financial resources | AW13: Staff training and professional development | AX13: 7 | AZ13: More than 50 years | BA13: I am aware of AI tools (e.g., ChatGPT, adaptive learning platforms) but have not used them | BB13: Some — infrastructure improvement (e.g., internet, devices) through a government programme | BC13: I am aware of it and have read parts of it | BD13: Fund infrastructure upgrades (internet, devices, electricity) directly | BE13: Support from an NGO or international development organisation | BF13: AI will be integrated into several teaching and administrative functions | BG13: The digital skills gap among students, not just staff | BH13: 1 | BI13: 1 | BJ13: 1 | BK13: 1 | BL13: 1 | BM13: 1 | BN13: 0
... A301: 300 | B301: 8/2/2026 8:27:15 | C301: Other | D301: Basic schools (primary + JHS) | E301: Greater Accra | F301: Public / Government | G301: 300 – 999 | H301: 20 – 49 | I301: Yes, but staffed part-time or informally | J301: 1 – 3 years | K301: 4 | L301: 4 | M301: 4 | N301: 3 | O301: 4 | P301: 2 | Q301: 3 | R301: 2 | S301: 3 | T301: 3 | U301: 4 | V301: 3 | W301: 4 | X301: 3 | Y301: 2 | Z301: 3 | AA301: 4 | AB301: 2 | AC301: 1 | AD301: 3 | AE301: 2 | AF301: 4 | AG301: 3 | AH301: 3 | AI301: 4 | AJ301: 2 | AK301: 3 | AL301: 4 | AM301: 3 | AN301: 3 | AO301: 2 | AP301: 2 | AQ301: 2 | AR301: 3 | AS301: 4 | AT301: Learning Management System (LMS) — e.g., Moodle, Google Classroom, School Management Information System (SMIS), Video conferencing or online learning platforms | AU301: Aware but no action — leadership is aware of AI tools but no steps have been taken | AV301: Insufficient financial resources | AW301: Technical infrastructure upgrades (internet, devices, power) | AX301: 4 | AZ301: 21 – 50 years | BA301: I am aware of AI tools (e.g., ChatGPT, adaptive learning platforms) but have not used them | BB301: Some — infrastructure improvement (e.g., internet, devices) through a government programme | BC301: I have heard of it but have not read it | BD301: All of the above — a comprehensive national AI-in-education strategy is needed | BE301: Support from an NGO or international development organisation | BF301: AI will be a core part of how we teach, assess, and manage the institution | BG301: Teacher resistance and the need for change management support | BH301: 1 | BI301: 1 | BJ301: 0 | BK301: 0 | BL301: 1 | BM301: 0 | BN301: 0

Sheet Modeling_Data
A1: RespondentID | B1: A1 | C1: A2 | D1: A5 | E1: A6 | F1: A7 | G1: A8 | H1: F1a | I1: F1b | J1: F1c | K1: F1d | L1: F1e | M1: F1f (rev) | N1: F2a | O1: F2b | P1: F2c | Q1: F2d | R1: F2e (rev) | S1: F3a | T1: F3b | U1: F3c | V1: F3d (rev) | W1: F4a | X1: F4b | Y1: F4c | Z1: F4d | AA1: F4e | AB1: F4f | AC1: F4g (rev) | AD1: F5a | AE1: F5b | AF1: F5c | AG1: F5d | AH1: F5e (rev) | AI1: F6a | AJ1: F6b | AK1: F6c | AL1: F6d (rev) | AM1: F7a | AN1: F7b | AO1: F7c | AP1: F7d (rev) | AQ1: F1_score | AR1: F2_score | AS1: F3_score | AT1: F3_reduced_score | AU1: F4_score | AV1: F5_score | AW1: F6_score | AX1: F7_score | AY1: Uses_LMS | AZ1: Uses_SMIS | BA1: Uses_AI_Teaching | BB1: Uses_AI_Admin | BC1: Uses_VideoConf | BD1: Uses_DigitalLibrary | BE1: C2 | BF1: C3 | BG1: C4 | BH1: C5 | BI1: D1 | BJ1: D2 | BK1: D3 | BL1: D4 | BM1: D5 | BN1: D6 | BO1: D7 | BP1: D8
A2: =Raw_Data!A2 -> 1 | B2: =Raw_Data!C2 -> Headteacher / Principal | C2: =Raw_Data!D2 -> Senior High School (SHS) | D2: =Raw_Data!G2 -> 1,000 – 4,999 | E2: =Raw_Data!H2 -> 50 – 99 | F2: =Raw_Data!I2 -> Yes, with dedicated full-time staff | G2: =Raw_Data!J2 -> 4 – 7 years | H2: =Raw_Data!K2 -> 5 | I2: =Raw_Data!L2 -> 5 | J2: =Raw_Data!M2 -> 4 | K2: =Raw_Data!N2 -> 4 | L2: =Raw_Data!O2 -> 5 | M2: =6-Raw_Data!P2 -> 5 | N2: =Raw_Data!Q2 -> 4 | O2: =Raw_Data!R2 -> 3 | P2: =Raw_Data!S2 -> 4 | Q2: =Raw_Data!T2 -> 4 | R2: =6-Raw_Data!U2 -> 4 | S2: =Raw_Data!V2 -> 4 | T2: =Raw_Data!W2 -> 5 | U2: =Raw_Data!X2 -> 3 | V2: =6-Raw_Data!Y2 -> 4 | W2: =Raw_Data!Z2 -> 4 | X2: =Raw_Data!AA2 -> 4 | Y2: =Raw_Data!AB2 -> 3 | Z2: =Raw_Data!AC2 -> 3 | AA2: =Raw_Data!AD2 -> 4 | AB2: =Raw_Data!AE2 -> 3 | AC2: =6-Raw_Data!AF2 -> 4 | AD2: =Raw_Data!AG2 -> 4 | AE2: =Raw_Data!AH2 -> 5 | AF2: =Raw_Data!AI2 -> 4 | AG2: =Raw_Data!AJ2 -> 3 | AH2: =6-Raw_Data!AK2 -> 4 | AI2: =Raw_Data!AL2 -> 4 | AJ2: =Raw_Data!AM2 -> 4 | AK2: =Raw_Data!AN2 -> 4 | AL2: =6-Raw_Data!AO2 -> 4 | AM2: =Raw_Data!AP2 -> 3 | AN2: =Raw_Data!AQ2 -> 2 | AO2: =Raw_Data!AR2 -> 4 | AP2: =6-Raw_Data!AS2 -> 3 | AQ2: =AVERAGE(Raw_Data!K2,Raw_Data!L2,Raw_Data!M2,Raw_Data!N2,Raw_Data!O2,(6-Raw_Data!P2)) -> 4.6666667 | AR2: =AVERAGE(Raw_Data!Q2,Raw_Data!R2,Raw_Data!S2,Raw_Data!T2,(6-Raw_Data!U2)) -> 3.8 | AS2: =AVERAGE(Raw_Data!V2,Raw_Data!W2,Raw_Data!X2,(6-Raw_Data!Y2)) -> 4 | AT2: =AVERAGE(Raw_Data!V2,Raw_Data!X2) -> 3.5 | AU2: =AVERAGE(Raw_Data!Z2,Raw_Data!AA2,Raw_Data!AB2,Raw_Data!AC2,Raw_Data!AD2,Raw_Data!AE2,(6-Raw_Data!AF2)) -> 3.5714286 | AV2: =AVERAGE(Raw_Data!AG2,Raw_Data!AH2,Raw_Data!AI2,Raw_Data!AJ2,(6-Raw_Data!AK2)) -> 4 | AW2: =AVERAGE(Raw_Data!AL2,Raw_Data!AM2,Raw_Data!AN2,(6-Raw_Data!AO2)) -> 4 | AX2: =AVERAGE(Raw_Data!AP2,Raw_Data!AQ2,Raw_Data!AR2,(6-Raw_Data!AS2)) -> 3 | AY2: =Raw_Data!BH2 -> 1 | AZ2: =Raw_Data!BI2 -> 1 | BA2: =Raw_Data!BJ2 -> 1 | BB2: =Raw_Data!BK2 -> 0 | BC2: =Raw_Data!BL2 -> 1 | BD2: =Raw_Data!BM2 -> 1 | BE2: =Raw_Data!AU2 -> Exploring — we are evaluating or piloting specific AI tools | BF2: =Raw_Data!AV2 -> Insufficient financial resources | BG2: =Raw_Data!AW2 -> Staff training and professional development | BH2: =Raw_Data!AX2 -> 7 | BI2: =Raw_Data!AZ2 -> More than 50 years | BJ2: =Raw_Data!BA2 -> I have personally tried one or more AI tools for education | BK2: =Raw_Data!BB2 -> Some — infrastructure improvement (e.g., internet, devices) through a government programme | BL2: =Raw_Data!BC2 -> I am aware of it and have read parts of it | BM2: =Raw_Data!BD2 -> All of the above — a comprehensive national AI-in-education strategy is needed | BN2: =Raw_Data!BE2 -> A relationship with a university or research institution | BO2: =Raw_Data!BF2 -> AI will be integrated into several teaching and administrative functions | BP2: =Raw_Data!BG2 -> The widening gap between well-resourced and under-resourced institutions
A3: =Raw_Data!A3 -> 2 | B3: =Raw_Data!C3 -> Other | C3: =Raw_Data!D3 -> Senior High School (SHS) | D3: =Raw_Data!G3 -> 1,000 – 4,999 | E3: =Raw_Data!H3 -> 50 – 99 | F3: =Raw_Data!I3 -> Yes, but staffed part-time or informally | G3: =Raw_Data!J3 -> 4 – 7 years | H3: =Raw_Data!K3 -> 5 | I3: =Raw_Data!L3 -> 5 | J3: =Raw_Data!M3 -> 4 | K3: =Raw_Data!N3 -> 4 | L3: =Raw_Data!O3 -> 5 | M3: =6-Raw_Data!P3 -> 2 | N3: =Raw_Data!Q3 -> 3 | O3: =Raw_Data!R3 -> 4 | P3: =Raw_Data!S3 -> 4 | Q3: =Raw_Data!T3 -> 2 | R3: =6-Raw_Data!U3 -> 2 | S3: =Raw_Data!V3 -> 5 | T3: =Raw_Data!W3 -> 3 | U3: =Raw_Data!X3 -> 5 | V3: =6-Raw_Data!Y3 -> 2 | W3: =Raw_Data!Z3 -> 5 | X3: =Raw_Data!AA3 -> 3 | Y3: =Raw_Data!AB3 -> 2 | Z3: =Raw_Data!AC3 -> 4 | AA3: =Raw_Data!AD3 -> 4 | AB3: =Raw_Data!AE3 -> 3 | AC3: =6-Raw_Data!AF3 -> 3 | AD3: =Raw_Data!AG3 -> 4 | AE3: =Raw_Data!AH3 -> 3 | AF3: =Raw_Data!AI3 -> 2 | AG3: =Raw_Data!AJ3 -> 4 | AH3: =6-Raw_Data!AK3 -> 1 | AI3: =Raw_Data!AL3 -> 4 | AJ3: =Raw_Data!AM3 -> 3 | AK3: =Raw_Data!AN3 -> 4 | AL3: =6-Raw_Data!AO3 -> 2 | AM3: =Raw_Data!AP3 -> 4 | AN3: =Raw_Data!AQ3 -> 2 | AO3: =Raw_Data!AR3 -> 5 | AP3: =6-Raw_Data!AS3 -> 2 | AQ3: =AVERAGE(Raw_Data!K3,Raw_Data!L3,Raw_Data!M3,Raw_Data!N3,Raw_Data!O3,(6-Raw_Data!P3)) -> 4.1666667 | AR3: =AVERAGE(Raw_Data!Q3,Raw_Data!R3,Raw_Data!S3,Raw_Data!T3,(6-Raw_Data!U3)) -> 3 | AS3: =AVERAGE(Raw_Data!V3,Raw_Data!W3,Raw_Data!X3,(6-Raw_Data!Y3)) -> 3.75 | AT3: =AVERAGE(Raw_Data!V3,Raw_Data!X3) -> 5 | AU3: =AVERAGE(Raw_Data!Z3,Raw_Data!AA3,Raw_Data!AB3,Raw_Data!AC3,Raw_Data!AD3,Raw_Data!AE3,(6-Raw_Data!AF3)) -> 3.4285714 | AV3: =AVERAGE(Raw_Data!AG3,Raw_Data!AH3,Raw_Data!AI3,Raw_Data!AJ3,(6-Raw_Data!AK3)) -> 2.8 | AW3: =AVERAGE(Raw_Data!AL3,Raw_Data!AM3,Raw_Data!AN3,(6-Raw_Data!AO3)) -> 3.25 | AX3: =AVERAGE(Raw_Data!AP3,Raw_Data!AQ3,Raw_Data!AR3,(6-Raw_Data!AS3)) -> 3.25 | AY3: =Raw_Data!BH3 -> 1 | AZ3: =Raw_Data!BI3 -> 0 | BA3: =Raw_Data!BJ3 -> 0 | BB3: =Raw_Data!BK3 -> 0 | BC3: =Raw_Data!BL3 -> 0 | BD3: =Raw_Data!BM3 -> 0 | BE3: =Raw_Data!AU3 -> Exploring — we are evaluating or piloting specific AI tools | BF3: =Raw_Data!AV3 -> Insufficient financial resources | BG3: =Raw_Data!AW3 -> Staff training and professional development | BH3: =Raw_Data!AX3 -> 7 | BI3: =Raw_Data!AZ3 -> More than 50 years | BJ3: =Raw_Data!BA3 -> I have no knowledge of what AI tools for education are | BK3: =Raw_Data!BB3 -> Some — infrastructure improvement (e.g., internet, devices) through a government programme | BL3: =Raw_Data!BC3 -> I am aware of it and have read parts of it | BM3: =Raw_Data!BD3 -> All of the above — a comprehensive national AI-in-education strategy is needed | BN3: =Raw_Data!BE3 -> Support from an NGO or international development organisation | BO3: =Raw_Data!BF3 -> AI will be integrated into several teaching and administrative functions | BP3: =Raw_Data!BG3 -> The widening gap between well-resourced and under-resourced institutions
A4: =Raw_Data!A4 -> 3 | B4: =Raw_Data!C4 -> Staff | C4: =Raw_Data!D4 -> Senior High School (SHS) | D4: =Raw_Data!G4 -> 1,000 – 4,999 | E4: =Raw_Data!H4 -> 50 – 99 | F4: =Raw_Data!I4 -> Yes, with dedicated full-time staff | G4: =Raw_Data!J4 -> 4 – 7 years | H4: =Raw_Data!K4 -> 5 | I4: =Raw_Data!L4 -> 5 | J4: =Raw_Data!M4 -> 4 | K4: =Raw_Data!N4 -> 4 | L4: =Raw_Data!O4 -> 5 | M4: =6-Raw_Data!P4 -> 5 | N4: =Raw_Data!Q4 -> 4 | O4: =Raw_Data!R4 -> 3 | P4: =Raw_Data!S4 -> 4 | Q4: =Raw_Data!T4 -> 4 | R4: =6-Raw_Data!U4 -> 4 | S4: =Raw_Data!V4 -> 4 | T4: =Raw_Data!W4 -> 5 | U4: =Raw_Data!X4 -> 3 | V4: =6-Raw_Data!Y4 -> 4 | W4: =Raw_Data!Z4 -> 4 | X4: =Raw_Data!AA4 -> 4 | Y4: =Raw_Data!AB4 -> 3 | Z4: =Raw_Data!AC4 -> 3 | AA4: =Raw_Data!AD4 -> 4 | AB4: =Raw_Data!AE4 -> 3 | AC4: =6-Raw_Data!AF4 -> 4 | AD4: =Raw_Data!AG4 -> 4 | AE4: =Raw_Data!AH4 -> 5 | AF4: =Raw_Data!AI4 -> 4 | AG4: =Raw_Data!AJ4 -> 3 | AH4: =6-Raw_Data!AK4 -> 4 | AI4: =Raw_Data!AL4 -> 4 | AJ4: =Raw_Data!AM4 -> 4 | AK4: =Raw_Data!AN4 -> 4 | AL4: =6-Raw_Data!AO4 -> 4 | AM4: =Raw_Data!AP4 -> 3 | AN4: =Raw_Data!AQ4 -> 2 | AO4: =Raw_Data!AR4 -> 3 | AP4: =6-Raw_Data!AS4 -> 2 | AQ4: =AVERAGE(Raw_Data!K4,Raw_Data!L4,Raw_Data!M4,Raw_Data!N4,Raw_Data!O4,(6-Raw_Data!P4)) -> 4.6666667 | AR4: =AVERAGE(Raw_Data!Q4,Raw_Data!R4,Raw_Data!S4,Raw_Data!T4,(6-Raw_Data!U4)) -> 3.8 | AS4: =AVERAGE(Raw_Data!V4,Raw_Data!W4,Raw_Data!X4,(6-Raw_Data!Y4)) -> 4 | AT4: =AVERAGE(Raw_Data!V4,Raw_Data!X4) -> 3.5 | AU4: =AVERAGE(Raw_Data!Z4,Raw_Data!AA4,Raw_Data!AB4,Raw_Data!AC4,Raw_Data!AD4,Raw_Data!AE4,(6-Raw_Data!AF4)) -> 3.5714286 | AV4: =AVERAGE(Raw_Data!AG4,Raw_Data!AH4,Raw_Data!AI4,Raw_Data!AJ4,(6-Raw_Data!AK4)) -> 4 | AW4: =AVERAGE(Raw_Data!AL4,Raw_Data!AM4,Raw_Data!AN4,(6-Raw_Data!AO4)) -> 4 | AX4: =AVERAGE(Raw_Data!AP4,Raw_Data!AQ4,Raw_Data!AR4,(6-Raw_Data!AS4)) -> 2.5 | AY4: =Raw_Data!BH4 -> 1 | AZ4: =Raw_Data!BI4 -> 1 | BA4: =Raw_Data!BJ4 -> 1 | BB4: =Raw_Data!BK4 -> 1 | BC4: =Raw_Data!BL4 -> 1 | BD4: =Raw_Data!BM4 -> 1 | BE4: =Raw_Data!AU4 -> Exploring — we are evaluating or piloting specific AI tools | BF4: =Raw_Data!AV4 -> Insufficient financial resources | BG4: =Raw_Data!AW4 -> Staff training and professional development | BH4: =Raw_Data!AX4 -> 7 | BI4: =Raw_Data!AZ4 -> More than 50 years | BJ4: =Raw_Data!BA4 -> I have personally tried one or more AI tools for education | BK4: =Raw_Data!BB4 -> Some — infrastructure improvement (e.g., internet, devices) through a government programme | BL4: =Raw_Data!BC4 -> I am aware of it and have read parts of it | BM4: =Raw_Data!BD4 -> All of the above — a comprehensive national AI-in-education strategy is needed | BN4: =Raw_Data!BE4 -> Support from an NGO or international development organisation | BO4: =Raw_Data!BF4 -> AI will be integrated into several teaching and administrative functions | BP4: =Raw_Data!BG4 -> The widening gap between well-resourced and under-resourced institutions
A5: =Raw_Data!A5 -> 4 | B5: =Raw_Data!C5 -> Staff | C5: =Raw_Data!D5 -> Senior High School (SHS) | D5: =Raw_Data!G5 -> 1,000 – 4,999 | E5: =Raw_Data!H5 -> 50 – 99 | F5: =Raw_Data!I5 -> Yes, with dedicated full-time staff | G5: =Raw_Data!J5 -> 4 – 7 years | H5: =Raw_Data!K5 -> 5 | I5: =Raw_Data!L5 -> 5 | J5: =Raw_Data!M5 -> 4 | K5: =Raw_Data!N5 -> 4 | L5: =Raw_Data!O5 -> 5 | M5: =6-Raw_Data!P5 -> 5 | N5: =Raw_Data!Q5 -> 4 | O5: =Raw_Data!R5 -> 3 | P5: =Raw_Data!S5 -> 4 | Q5: =Raw_Data!T5 -> 4 | R5: =6-Raw_Data!U5 -> 4 | S5: =Raw_Data!V5 -> 4 | T5: =Raw_Data!W5 -> 5 | U5: =Raw_Data!X5 -> 3 | V5: =6-Raw_Data!Y5 -> 4 | W5: =Raw_Data!Z5 -> 4 | X5: =Raw_Data!AA5 -> 4 | Y5: =Raw_Data!AB5 -> 3 | Z5: =Raw_Data!AC5 -> 3 | AA5: =Raw_Data!AD5 -> 4 | AB5: =Raw_Data!AE5 -> 3 | AC5: =6-Raw_Data!AF5 -> 4 | AD5: =Raw_Data!AG5 -> 4 | AE5: =Raw_Data!AH5 -> 5 | AF5: =Raw_Data!AI5 -> 4 | AG5: =Raw_Data!AJ5 -> 3 | AH5: =6-Raw_Data!AK5 -> 4 | AI5: =Raw_Data!AL5 -> 4 | AJ5: =Raw_Data!AM5 -> 4 | AK5: =Raw_Data!AN5 -> 4 | AL5: =6-Raw_Data!AO5 -> 4 | AM5: =Raw_Data!AP5 -> 3 | AN5: =Raw_Data!AQ5 -> 2 | AO5: =Raw_Data!AR5 -> 3 | AP5: =6-Raw_Data!AS5 -> 2 | AQ5: =AVERAGE(Raw_Data!K5,Raw_Data!L5,Raw_Data!M5,Raw_Data!N5,Raw_Data!O5,(6-Raw_Data!P5)) -> 4.6666667 | AR5: =AVERAGE(Raw_Data!Q5,Raw_Data!R5,Raw_Data!S5,Raw_Data!T5,(6-Raw_Data!U5)) -> 3.8 | AS5: =AVERAGE(Raw_Data!V5,Raw_Data!W5,Raw_Data!X5,(6-Raw_Data!Y5)) -> 4 | AT5: =AVERAGE(Raw_Data!V5,Raw_Data!X5) -> 3.5 | AU5: =AVERAGE(Raw_Data!Z5,Raw_Data!AA5,Raw_Data!AB5,Raw_Data!AC5,Raw_Data!AD5,Raw_Data!AE5,(6-Raw_Data!AF5)) -> 3.5714286 | AV5: =AVERAGE(Raw_Data!AG5,Raw_Data!AH5,Raw_Data!AI5,Raw_Data!AJ5,(6-Raw_Data!AK5)) -> 4 | AW5: =AVERAGE(Raw_Data!AL5,Raw_Data!AM5,Raw_Data!AN5,(6-Raw_Data!AO5)) -> 4 | AX5: =AVERAGE(Raw_Data!AP5,Raw_Data!AQ5,Raw_Data!AR5,(6-Raw_Data!AS5)) -> 2.5 | AY5: =Raw_Data!BH5 -> 1 | AZ5: =Raw_Data!BI5 -> 1 | BA5: =Raw_Data!BJ5 -> 1 | BB5: =Raw_Data!BK5 -> 1 | BC5: =Raw_Data!BL5 -> 1 | BD5: =Raw_Data!BM5 -> 1 | BE5: =Raw_Data!AU5 -> Exploring — we are evaluating or piloting specific AI tools | BF5: =Raw_Data!AV5 -> Insufficient financial resources | BG5: =Raw_Data!AW5 -> Staff training and professional development | BH5: =Raw_Data!AX5 -> 7 | BI5: =Raw_Data!AZ5 -> More than 50 years | BJ5: =Raw_Data!BA5 -> I have personally tried one or more AI tools for education | BK5: =Raw_Data!BB5 -> Some — infrastructure improvement (e.g., internet, devices) through a government programme | BL5: =Raw_Data!BC5 -> I am aware of it and have read parts of it | BM5: =Raw_Data!BD5 -> All of the above — a comprehensive national AI-in-education strategy is needed | BN5: =Raw_Data!BE5 -> Support from an NGO or international development organisation | BO5: =Raw_Data!BF5 -> AI will be integrated into several teaching and administrative functions | BP5: =Raw_Data!BG5 -> The widening gap between well-resourced and under-resourced institutions
A6: =Raw_Data!A6 -> 5 | B6: =Raw_Data!C6 -> Staff | C6: =Raw_Data!D6 -> Senior High School (SHS) | D6: =Raw_Data!G6 -> 1,000 – 4,999 | E6: =Raw_Data!H6 -> 50 – 99 | F6: =Raw_Data!I6 -> Yes, with dedicated full-time staff | G6: =Raw_Data!J6 -> 4 – 7 years | H6: =Raw_Data!K6 -> 5 | I6: =Raw_Data!L6 -> 5 | J6: =Raw_Data!M6 -> 4 | K6: =Raw_Data!N6 -> 4 | L6: =Raw_Data!O6 -> 5 | M6: =6-Raw_Data!P6 -> 5 | N6: =Raw_Data!Q6 -> 4 | O6: =Raw_Data!R6 -> 3 | P6: =Raw_Data!S6 -> 4 | Q6: =Raw_Data!T6 -> 4 | R6: =6-Raw_Data!U6 -> 4 | S6: =Raw_Data!V6 -> 4 | T6: =Raw_Data!W6 -> 5 | U6: =Raw_Data!X6 -> 3 | V6: =6-Raw_Data!Y6 -> 4 | W6: =Raw_Data!Z6 -> 4 | X6: =Raw_Data!AA6 -> 4 | Y6: =Raw_Data!AB6 -> 3 | Z6: =Raw_Data!AC6 -> 3 | AA6: =Raw_Data!AD6 -> 4 | AB6: =Raw_Data!AE6 -> 3 | AC6: =6-Raw_Data!AF6 -> 4 | AD6: =Raw_Data!AG6 -> 4 | AE6: =Raw_Data!AH6 -> 5 | AF6: =Raw_Data!AI6 -> 4 | AG6: =Raw_Data!AJ6 -> 3 | AH6: =6-Raw_Data!AK6 -> 4 | AI6: =Raw_Data!AL6 -> 4 | AJ6: =Raw_Data!AM6 -> 4 | AK6: =Raw_Data!AN6 -> 4 | AL6: =6-Raw_Data!AO6 -> 4 | AM6: =Raw_Data!AP6 -> 3 | AN6: =Raw_Data!AQ6 -> 2 | AO6: =Raw_Data!AR6 -> 3 | AP6: =6-Raw_Data!AS6 -> 2 | AQ6: =AVERAGE(Raw_Data!K6,Raw_Data!L6,Raw_Data!M6,Raw_Data!N6,Raw_Data!O6,(6-Raw_Data!P6)) -> 4.6666667 | AR6: =AVERAGE(Raw_Data!Q6,Raw_Data!R6,Raw_Data!S6,Raw_Data!T6,(6-Raw_Data!U6)) -> 3.8 | AS6: =AVERAGE(Raw_Data!V6,Raw_Data!W6,Raw_Data!X6,(6-Raw_Data!Y6)) -> 4 | AT6: =AVERAGE(Raw_Data!V6,Raw_Data!X6) -> 3.5 | AU6: =AVERAGE(Raw_Data!Z6,Raw_Data!AA6,Raw_Data!AB6,Raw_Data!AC6,Raw_Data!AD6,Raw_Data!AE6,(6-Raw_Data!AF6)) -> 3.5714286 | AV6: =AVERAGE(Raw_Data!AG6,Raw_Data!AH6,Raw_Data!AI6,Raw_Data!AJ6,(6-Raw_Data!AK6)) -> 4 | AW6: =AVERAGE(Raw_Data!AL6,Raw_Data!AM6,Raw_Data!AN6,(6-Raw_Data!AO6)) -> 4 | AX6: =AVERAGE(Raw_Data!AP6,Raw_Data!AQ6,Raw_Data!AR6,(6-Raw_Data!AS6)) -> 2.5 | AY6: =Raw_Data!BH6 -> 1 | AZ6: =Raw_Data!BI6 -> 1 | BA6: =Raw_Data!BJ6 -> 1 | BB6: =Raw_Data!BK6 -> 1 | BC6: =Raw_Data!BL6 -> 1 | BD6: =Raw_Data!BM6 -> 1 | BE6: =Raw_Data!AU6 -> Exploring — we are evaluating or piloting specific AI tools | BF6: =Raw_Data!AV6 -> Insufficient financial resources | BG6: =Raw_Data!AW6 -> Staff training and professional development | BH6: =Raw_Data!AX6 -> 7 | BI6: =Raw_Data!AZ6 -> More than 50 years | BJ6: =Raw_Data!BA6 -> I have personally tried one or more AI tools for education | BK6: =Raw_Data!BB6 -> Some — infrastructure improvement (e.g., internet, devices) through a government programme | BL6: =Raw_Data!BC6 -> I am aware of it and have read parts of it | BM6: =Raw_Data!BD6 -> All of the above — a comprehensive national AI-in-education strategy is needed | BN6: =Raw_Data!BE6 -> Support from an NGO or international development organisation | BO6: =Raw_Data!BF6 -> AI will be integrated into several teaching and administrative functions | BP6: =Raw_Data!BG6 -> The widening gap between well-resourced and under-resourced institutions
A7: =Raw_Data!A7 -> 6 | B7: =Raw_Data!C7 -> Staff | C7: =Raw_Data!D7 -> Senior High School (SHS) | D7: =Raw_Data!G7 -> 1,000 – 4,999 | E7: =Raw_Data!H7 -> 50 – 99 | F7: =Raw_Data!I7 -> Yes, with dedicated full-time staff | G7: =Raw_Data!J7 -> 4 – 7 years | H7: =Raw_Data!K7 -> 5 | I7: =Raw_Data!L7 -> 5 | J7: =Raw_Data!M7 -> 4 | K7: =Raw_Data!N7 -> 4 | L7: =Raw_Data!O7 -> 5 | M7: =6-Raw_Data!P7 -> 5 | N7: =Raw_Data!Q7 -> 4 | O7: =Raw_Data!R7 -> 3 | P7: =Raw_Data!S7 -> 4 | Q7: =Raw_Data!T7 -> 4 | R7: =6-Raw_Data!U7 -> 4 | S7: =Raw_Data!V7 -> 4 | T7: =Raw_Data!W7 -> 5 | U7: =Raw_Data!X7 -> 3 | V7: =6-Raw_Data!Y7 -> 4 | W7: =Raw_Data!Z7 -> 4 | X7: =Raw_Data!AA7 -> 4 | Y7: =Raw_Data!AB7 -> 3 | Z7: =Raw_Data!AC7 -> 3 | AA7: =Raw_Data!AD7 -> 4 | AB7: =Raw_Data!AE7 -> 3 | AC7: =6-Raw_Data!AF7 -> 4 | AD7: =Raw_Data!AG7 -> 4 | AE7: =Raw_Data!AH7 -> 5 | AF7: =Raw_Data!AI7 -> 4 | AG7: =Raw_Data!AJ7 -> 3 | AH7: =6-Raw_Data!AK7 -> 4 | AI7: =Raw_Data!AL7 -> 4 | AJ7: =Raw_Data!AM7 -> 4 | AK7: =Raw_Data!AN7 -> 4 | AL7: =6-Raw_Data!AO7 -> 4 | AM7: =Raw_Data!AP7 -> 3 | AN7: =Raw_Data!AQ7 -> 2 | AO7: =Raw_Data!AR7 -> 3 | AP7: =6-Raw_Data!AS7 -> 2 | AQ7: =AVERAGE(Raw_Data!K7,Raw_Data!L7,Raw_Data!M7,Raw_Data!N7,Raw_Data!O7,(6-Raw_Data!P7)) -> 4.6666667 | AR7: =AVERAGE(Raw_Data!Q7,Raw_Data!R7,Raw_Data!S7,Raw_Data!T7,(6-Raw_Data!U7)) -> 3.8 | AS7: =AVERAGE(Raw_Data!V7,Raw_Data!W7,Raw_Data!X7,(6-Raw_Data!Y7)) -> 4 | AT7: =AVERAGE(Raw_Data!V7,Raw_Data!X7) -> 3.5 | AU7: =AVERAGE(Raw_Data!Z7,Raw_Data!AA7,Raw_Data!AB7,Raw_Data!AC7,Raw_Data!AD7,Raw_Data!AE7,(6-Raw_Data!AF7)) -> 3.5714286 | AV7: =AVERAGE(Raw_Data!AG7,Raw_Data!AH7,Raw_Data!AI7,Raw_Data!AJ7,(6-Raw_Data!AK7)) -> 4 | AW7: =AVERAGE(Raw_Data!AL7,Raw_Data!AM7,Raw_Data!AN7,(6-Raw_Data!AO7)) -> 4 | AX7: =AVERAGE(Raw_Data!AP7,Raw_Data!AQ7,Raw_Data!AR7,(6-Raw_Data!AS7)) -> 2.5 | AY7: =Raw_Data!BH7 -> 1 | AZ7: =Raw_Data!BI7 -> 1 | BA7: =Raw_Data!BJ7 -> 1 | BB7: =Raw_Data!BK7 -> 1 | BC7: =Raw_Data!BL7 -> 1 | BD7: =Raw_Data!BM7 -> 1 | BE7: =Raw_Data!AU7 -> Exploring — we are evaluating or piloting specific AI tools | BF7: =Raw_Data!AV7 -> Insufficient financial resources | BG7: =Raw_Data!AW7 -> Staff training and professional development | BH7: =Raw_Data!AX7 -> 7 | BI7: =Raw_Data!AZ7 -> More than 50 years | BJ7: =Raw_Data!BA7 -> I have personally tried one or more AI tools for education | BK7: =Raw_Data!BB7 -> Some — infrastructure improvement (e.g., internet, devices) through a government programme | BL7: =Raw_Data!BC7 -> I am aware of it and have read parts of it | BM7: =Raw_Data!BD7 -> All of the above — a comprehensive national AI-in-education strategy is needed | BN7: =Raw_Data!BE7 -> Support from an NGO or international development organisation | BO7: =Raw_Data!BF7 -> AI will be integrated into several teaching and administrative functions | BP7: =Raw_Data!BG7 -> The widening gap between well-resourced and under-resourced institutions
A8: =Raw_Data!A8 -> 7 | B8: =Raw_Data!C8 -> Staff | C8: =Raw_Data!D8 -> Senior High School (SHS) | D8: =Raw_Data!G8 -> 1,000 – 4,999 | E8: =Raw_Data!H8 -> 50 – 99 | F8: =Raw_Data!I8 -> Yes, with dedicated full-time staff | G8: =Raw_Data!J8 -> More than 15 years | H8: =Raw_Data!K8 -> 5 | I8: =Raw_Data!L8 -> 4 | J8: =Raw_Data!M8 -> 4 | K8: =Raw_Data!N8 -> 5 | L8: =Raw_Data!O8 -> 4 | M8: =6-Raw_Data!P8 -> 2 | N8: =Raw_Data!Q8 -> 4 | O8: =Raw_Data!R8 -> 5 | P8: =Raw_Data!S8 -> 5 | Q8: =Raw_Data!T8 -> 5 | R8: =6-Raw_Data!U8 -> 3 | S8: =Raw_Data!V8 -> 4 | T8: =Raw_Data!W8 -> 4 | U8: =Raw_Data!X8 -> 4 | V8: =6-Raw_Data!Y8 -> 3 | W8: =Raw_Data!Z8 -> 5 | X8: =Raw_Data!AA8 -> 4 | Y8: =Raw_Data!AB8 -> 4 | Z8: =Raw_Data!AC8 -> 3 | AA8: =Raw_Data!AD8 -> 3 | AB8: =Raw_Data!AE8 -> 4 | AC8: =6-Raw_Data!AF8 -> 2 | AD8: =Raw_Data!AG8 -> 4 | AE8: =Raw_Data!AH8 -> 5 | AF8: =Raw_Data!AI8 -> 5 | AG8: =Raw_Data!AJ8 -> 5 | AH8: =6-Raw_Data!AK8 -> 2 | AI8: =Raw_Data!AL8 -> 4 | AJ8: =Raw_Data!AM8 -> 5 | AK8: =Raw_Data!AN8 -> 5 | AL8: =6-Raw_Data!AO8 -> 2 | AM8: =Raw_Data!AP8 -> 5 | AN8: =Raw_Data!AQ8 -> 4 | AO8: =Raw_Data!AR8 -> 5 | AP8: =6-Raw_Data!AS8 -> 1 | AQ8: =AVERAGE(Raw_Data!K8,Raw_Data!L8,Raw_Data!M8,Raw_Data!N8,Raw_Data!O8,(6-Raw_Data!P8)) -> 4 | AR8: =AVERAGE(Raw_Data!Q8,Raw_Data!R8,Raw_Data!S8,Raw_Data!T8,(6-Raw_Data!U8)) -> 4.4 | AS8: =AVERAGE(Raw_Data!V8,Raw_Data!W8,Raw_Data!X8,(6-Raw_Data!Y8)) -> 3.75 | AT8: =AVERAGE(Raw_Data!V8,Raw_Data!X8) -> 4 | AU8: =AVERAGE(Raw_Data!Z8,Raw_Data!AA8,Raw_Data!AB8,Raw_Data!AC8,Raw_Data!AD8,Raw_Data!AE8,(6-Raw_Data!AF8)) -> 3.5714286 | AV8: =AVERAGE(Raw_Data!AG8,Raw_Data!AH8,Raw_Data!AI8,Raw_Data!AJ8,(6-Raw_Data!AK8)) -> 4.2 | AW8: =AVERAGE(Raw_Data!AL8,Raw_Data!AM8,Raw_Data!AN8,(6-Raw_Data!AO8)) -> 4 | AX8: =AVERAGE(Raw_Data!AP8,Raw_Data!AQ8,Raw_Data!AR8,(6-Raw_Data!AS8)) -> 3.75 | AY8: =Raw_Data!BH8 -> 0 | AZ8: =Raw_Data!BI8 -> 0 | BA8: =Raw_Data!BJ8 -> 1 | BB8: =Raw_Data!BK8 -> 0 | BC8: =Raw_Data!BL8 -> 0 | BD8: =Raw_Data!BM8 -> 0 | BE8: =Raw_Data!AU8 -> Exploring — we are evaluating or piloting specific AI tools | BF8: =Raw_Data!AV8 -> Insufficient financial resources | BG8: =Raw_Data!AW8 -> Staff training and professional development | BH8: =Raw_Data!AX8 -> 7 | BI8: =Raw_Data!AZ8 -> More than 50 years | BJ8: =Raw_Data!BA8 -> I am aware of AI tools (e.g., ChatGPT, adaptive learning platforms) but have not used them | BK8: =Raw_Data!BB8 -> Some — infrastructure improvement (e.g., internet, devices) through a government programme | BL8: =Raw_Data!BC8 -> I am familiar with it but it has had no practical impact at my institution | BM8: =Raw_Data!BD8 -> All of the above — a comprehensive national AI-in-education strategy is needed | BN8: =Raw_Data!BE8 -> Support from an NGO or international development organisation | BO8: =Raw_Data!BF8 -> AI will be integrated into several teaching and administrative functions | BP8: =Raw_Data!BG8 -> The widening gap between well-resourced and under-resourced institutions
A9: =Raw_Data!A9 -> 8 | B9: =Raw_Data!C9 -> Staff | C9: =Raw_Data!D9 -> Senior High School (SHS) | D9: =Raw_Data!G9 -> 1,000 – 4,999 | E9: =Raw_Data!H9 -> 20 – 49 | F9: =Raw_Data!I9 -> Yes, but staffed part-time or informally | G9: =Raw_Data!J9 -> More than 15 years | H9: =Raw_Data!K9 -> 4 | I9: =Raw_Data!L9 -> 3 | J9: =Raw_Data!M9 -> 3 | K9: =Raw_Data!N9 -> 3 | L9: =Raw_Data!O9 -> 4 | M9: =6-Raw_Data!P9 -> 1 | N9: =Raw_Data!Q9 -> 5 | O9: =Raw_Data!R9 -> 5 | P9: =Raw_Data!S9 -> 4 | Q9: =Raw_Data!T9 -> 4 | R9: =6-Raw_Data!U9 -> 2 | S9: =Raw_Data!V9 -> 3 | T9: =Raw_Data!W9 -> 2 | U9: =Raw_Data!X9 -> 5 | V9: =6-Raw_Data!Y9 -> 1 | W9: =Raw_Data!Z9 -> 4 | X9: =Raw_Data!AA9 -> 4 | Y9: =Raw_Data!AB9 -> 4 | Z9: =Raw_Data!AC9 -> 4 | AA9: =Raw_Data!AD9 -> 3 | AB9: =Raw_Data!AE9 -> 5 | AC9: =6-Raw_Data!AF9 -> 3 | AD9: =Raw_Data!AG9 -> 2 | AE9: =Raw_Data!AH9 -> 4 | AF9: =Raw_Data!AI9 -> 3 | AG9: =Raw_Data!AJ9 -> 5 | AH9: =6-Raw_Data!AK9 -> 1 | AI9: =Raw_Data!AL9 -> 5 | AJ9: =Raw_Data!AM9 -> 4 | AK9: =Raw_Data!AN9 -> 4 | AL9: =6-Raw_Data!AO9 -> 1 | AM9: =Raw_Data!AP9 -> 5 | AN9: =Raw_Data!AQ9 -> 4 | AO9: =Raw_Data!AR9 -> 4 | AP9: =6-Raw_Data!AS9 -> 2 | AQ9: =AVERAGE(Raw_Data!K9,Raw_Data!L9,Raw_Data!M9,Raw_Data!N9,Raw_Data!O9,(6-Raw_Data!P9)) -> 3 | AR9: =AVERAGE(Raw_Data!Q9,Raw_Data!R9,Raw_Data!S9,Raw_Data!T9,(6-Raw_Data!U9)) -> 4 | AS9: =AVERAGE(Raw_Data!V9,Raw_Data!W9,Raw_Data!X9,(6-Raw_Data!Y9)) -> 2.75 | AT9: =AVERAGE(Raw_Data!V9,Raw_Data!X9) -> 4 | AU9: =AVERAGE(Raw_Data!Z9,Raw_Data!AA9,Raw_Data!AB9,Raw_Data!AC9,Raw_Data!AD9,Raw_Data!AE9,(6-Raw_Data!AF9)) -> 3.8571429 | AV9: =AVERAGE(Raw_Data!AG9,Raw_Data!AH9,Raw_Data!AI9,Raw_Data!AJ9,(6-Raw_Data!AK9)) -> 3 | AW9: =AVERAGE(Raw_Data!AL9,Raw_Data!AM9,Raw_Data!AN9,(6-Raw_Data!AO9)) -> 3.5 | AX9: =AVERAGE(Raw_Data!AP9,Raw_Data!AQ9,Raw_Data!AR9,(6-Raw_Data!AS9)) -> 3.75 | AY9: =Raw_Data!BH9 -> 0 | AZ9: =Raw_Data!BI9 -> 0 | BA9: =Raw_Data!BJ9 -> 0 | BB9: =Raw_Data!BK9 -> 1 | BC9: =Raw_Data!BL9 -> 0 | BD9: =Raw_Data!BM9 -> 0 | BE9: =Raw_Data!AU9 -> Exploring — we are evaluating or piloting specific AI tools | BF9: =Raw_Data!AV9 -> Insufficient financial resources | BG9: =Raw_Data!AW9 -> Staff training and professional development | BH9: =Raw_Data!AX9 -> 8 | BI9: =Raw_Data!AZ9 -> More than 50 years | BJ9: =Raw_Data!BA9 -> I am aware of AI tools (e.g., ChatGPT, adaptive learning platforms) but have not used them | BK9: =Raw_Data!BB9 -> Some — infrastructure improvement (e.g., internet, devices) through a government programme | BL9: =Raw_Data!BC9 -> I am aware of it and have read parts of it | BM9: =Raw_Data!BD9 -> All of the above — a comprehensive national AI-in-education strategy is needed | BN9: =Raw_Data!BE9 -> Support from an NGO or international development organisation | BO9: =Raw_Data!BF9 -> AI will be integrated into several teaching and administrative functions | BP9: =Raw_Data!BG9 -> The absence of data privacy frameworks and ethical guidelines
A10: =Raw_Data!A10 -> 9 | B10: =Raw_Data!C10 -> Other | C10: =Raw_Data!D10 -> Senior High School (SHS) | D10: =Raw_Data!G10 -> 1,000 – 4,999 | E10: =Raw_Data!H10 -> 50 – 99 | F10: =Raw_Data!I10 -> Yes, with dedicated full-time staff | G10: =Raw_Data!J10 -> 8 – 15 years | H10: =Raw_Data!K10 -> 4 | I10: =Raw_Data!L10 -> 4 | J10: =Raw_Data!M10 -> 5 | K10: =Raw_Data!N10 -> 5 | L10: =Raw_Data!O10 -> 3 | M10: =6-Raw_Data!P10 -> 2 | N10: =Raw_Data!Q10 -> 5 | O10: =Raw_Data!R10 -> 3 | P10: =Raw_Data!S10 -> 3 | Q10: =Raw_Data!T10 -> 4 | R10: =6-Raw_Data!U10 -> 4 | S10: =Raw_Data!V10 -> 4 | T10: =Raw_Data!W10 -> 4 | U10: =Raw_Data!X10 -> 4 | V10: =6-Raw_Data!Y10 -> 1 | W10: =Raw_Data!Z10 -> 4 | X10: =Raw_Data!AA10 -> 4 | Y10: =Raw_Data!AB10 -> 4 | Z10: =Raw_Data!AC10 -> 4 | AA10: =Raw_Data!AD10 -> 3 | AB10: =Raw_Data!AE10 -> 2 | AC10: =6-Raw_Data!AF10 -> 4 | AD10: =Raw_Data!AG10 -> 3 | AE10: =Raw_Data!AH10 -> 2 | AF10: =Raw_Data!AI10 -> 4 | AG10: =Raw_Data!AJ10 -> 4 | AH10: =6-Raw_Data!AK10 -> 4 | AI10: =Raw_Data!AL10 -> 3 | AJ10: =Raw_Data!AM10 -> 5 | AK10: =Raw_Data!AN10 -> 5 | AL10: =6-Raw_Data!AO10 -> 1 | AM10: =Raw_Data!AP10 -> 5 | AN10: =Raw_Data!AQ10 -> 5 | AO10: =Raw_Data!AR10 -> 4 | AP10: =6-Raw_Data!AS10 -> 2 | AQ10: =AVERAGE(Raw_Data!K10,Raw_Data!L10,Raw_Data!M10,Raw_Data!N10,Raw_Data!O10,(6-Raw_Data!P10)) -> 3.8333333 | AR10: =AVERAGE(Raw_Data!Q10,Raw_Data!R10,Raw_Data!S10,Raw_Data!T10,(6-Raw_Data!U10)) -> 3.8 | AS10: =AVERAGE(Raw_Data!V10,Raw_Data!W10,Raw_Data!X10,(6-Raw_Data!Y10)) -> 3.25 | AT10: =AVERAGE(Raw_Data!V10,Raw_Data!X10) -> 4 | AU10: =AVERAGE(Raw_Data!Z10,Raw_Data!AA10,Raw_Data!AB10,Raw_Data!AC10,Raw_Data!AD10,Raw_Data!AE10,(6-Raw_Data!AF10)) -> 3.5714286 | AV10: =AVERAGE(Raw_Data!AG10,Raw_Data!AH10,Raw_Data!AI10,Raw_Data!AJ10,(6-Raw_Data!AK10)) -> 3.4 | AW10: =AVERAGE(Raw_Data!AL10,Raw_Data!AM10,Raw_Data!AN10,(6-Raw_Data!AO10)) -> 3.5 | AX10: =AVERAGE(Raw_Data!AP10,Raw_Data!AQ10,Raw_Data!AR10,(6-Raw_Data!AS10)) -> 4 | AY10: =Raw_Data!BH10 -> 0 | AZ10: =Raw_Data!BI10 -> 0 | BA10: =Raw_Data!BJ10 -> 1 | BB10: =Raw_Data!BK10 -> 0 | BC10: =Raw_Data!BL10 -> 0 | BD10: =Raw_Data!BM10 -> 0 | BE10: =Raw_Data!AU10 -> Exploring — we are evaluating or piloting specific AI tools | BF10: =Raw_Data!AV10 -> Insufficient financial resources | BG10: =Raw_Data!AW10 -> Staff training and professional development | BH10: =Raw_Data!AX10 -> 9 | BI10: =Raw_Data!AZ10 -> More than 50 years | BJ10: =Raw_Data!BA10 -> I am aware of AI tools (e.g., ChatGPT, adaptive learning platforms) but have not used them | BK10: =Raw_Data!BB10 -> Yes — meaningful support from an NGO, private company, or international organisation | BL10: =Raw_Data!BC10 -> I am aware of it and have read parts of it | BM10: =Raw_Data!BD10 -> All of the above — a comprehensive national AI-in-education strategy is needed | BN10: =Raw_Data!BE10 -> Support from an NGO or international development organisation | BO10: =Raw_Data!BF10 -> AI will be integrated into several teaching and administrative functions | BP10: =Raw_Data!BG10 -> The widening gap between well-resourced and under-resourced institutions
A11: =Raw_Data!A11 -> 10 | B11: =Raw_Data!C11 -> Other | C11: =Raw_Data!D11 -> Senior High School (SHS) | D11: =Raw_Data!G11 -> 1,000 – 4,999 | E11: =Raw_Data!H11 -> 50 – 99 | F11: =Raw_Data!I11 -> Yes, with dedicated full-time staff | G11: =Raw_Data!J11 -> 8 – 15 years | H11: =Raw_Data!K11 -> 5 | I11: =Raw_Data!L11 -> 5 | J11: =Raw_Data!M11 -> 4 | K11: =Raw_Data!N11 -> 4 | L11: =Raw_Data!O11 -> 4 | M11: =6-Raw_Data!P11 -> 3 | N11: =Raw_Data!Q11 -> 4 | O11: =Raw_Data!R11 -> 4 | P11: =Raw_Data!S11 -> 4 | Q11: =Raw_Data!T11 -> 4 | R11: =6-Raw_Data!U11 -> 3 | S11: =Raw_Data!V11 -> 3 | T11: =Raw_Data!W11 -> 4 | U11: =Raw_Data!X11 -> 3 | V11: =6-Raw_Data!Y11 -> 2 | W11: =Raw_Data!Z11 -> 5 | X11: =Raw_Data!AA11 -> 4 | Y11: =Raw_Data!AB11 -> 3 | Z11: =Raw_Data!AC11 -> 4 | AA11: =Raw_Data!AD11 -> 2 | AB11: =Raw_Data!AE11 -> 2 | AC11: =6-Raw_Data!AF11 -> 1 | AD11: =Raw_Data!AG11 -> 4 | AE11: =Raw_Data!AH11 -> 4 | AF11: =Raw_Data!AI11 -> 4 | AG11: =Raw_Data!AJ11 -> 5 | AH11: =6-Raw_Data!AK11 -> 1 | AI11: =Raw_Data!AL11 -> 4 | AJ11: =Raw_Data!AM11 -> 5 | AK11: =Raw_Data!AN11 -> 5 | AL11: =6-Raw_Data!AO11 -> 2 | AM11: =Raw_Data!AP11 -> 3 | AN11: =Raw_Data!AQ11 -> 3 | AO11: =Raw_Data!AR11 -> 1 | AP11: =6-Raw_Data!AS11 -> 2 | AQ11: =AVERAGE(Raw_Data!K11,Raw_Data!L11,Raw_Data!M11,Raw_Data!N11,Raw_Data!O11,(6-Raw_Data!P11)) -> 4.1666667 | AR11: =AVERAGE(Raw_Data!Q11,Raw_Data!R11,Raw_Data!S11,Raw_Data!T11,(6-Raw_Data!U11)) -> 3.8 | AS11: =AVERAGE(Raw_Data!V11,Raw_Data!W11,Raw_Data!X11,(6-Raw_Data!Y11)) -> 3 | AT11: =AVERAGE(Raw_Data!V11,Raw_Data!X11) -> 3 | AU11: =AVERAGE(Raw_Data!Z11,Raw_Data!AA11,Raw_Data!AB11,Raw_Data!AC11,Raw_Data!AD11,Raw_Data!AE11,(6-Raw_Data!AF11)) -> 3 | AV11: =AVERAGE(Raw_Data!AG11,Raw_Data!AH11,Raw_Data!AI11,Raw_Data!AJ11,(6-Raw_Data!AK11)) -> 3.6 | AW11: =AVERAGE(Raw_Data!AL11,Raw_Data!AM11,Raw_Data!AN11,(6-Raw_Data!AO11)) -> 4 | AX11: =AVERAGE(Raw_Data!AP11,Raw_Data!AQ11,Raw_Data!AR11,(6-Raw_Data!AS11)) -> 2.25 | AY11: =Raw_Data!BH11 -> 0 | AZ11: =Raw_Data!BI11 -> 0 | BA11: =Raw_Data!BJ11 -> 1 | BB11: =Raw_Data!BK11 -> 0 | BC11: =Raw_Data!BL11 -> 0 | BD11: =Raw_Data!BM11 -> 0 | BE11: =Raw_Data!AU11 -> Exploring — we are evaluating or piloting specific AI tools | BF11: =Raw_Data!AV11 -> Insufficient financial resources | BG11: =Raw_Data!AW11 -> Staff training and professional development | BH11: =Raw_Data!AX11 -> 7 | BI11: =Raw_Data!AZ11 -> More than 50 years | BJ11: =Raw_Data!BA11 -> I am aware of AI tools (e.g., ChatGPT, adaptive learning platforms) but have not used them | BK11: =Raw_Data!BB11 -> Yes — ongoing partnership with consistent technology support | BL11: =Raw_Data!BC11 -> I am familiar with it but it has had no practical impact at my institution | BM11: =Raw_Data!BD11 -> All of the above — a comprehensive national AI-in-education strategy is needed | BN11: =Raw_Data!BE11 -> Support from an NGO or international development organisation | BO11: =Raw_Data!BF11 -> AI will be integrated into several teaching and administrative functions | BP11: =Raw_Data!BG11 -> The widening gap between well-resourced and under-resourced institutions
A12: =Raw_Data!A12 -> 11 | B12: =Raw_Data!C12 -> Staff | C12: =Raw_Data!D12 -> Senior High School (SHS) | D12: =Raw_Data!G12 -> 1,000 – 4,999 | E12: =Raw_Data!H12 -> 50 – 99 | F12: =Raw_Data!I12 -> Yes, with dedicated full-time staff | G12: =Raw_Data!J12 -> More than 15 years | H12: =Raw_Data!K12 -> 3 | I12: =Raw_Data!L12 -> 4 | J12: =Raw_Data!M12 -> 5 | K12: =Raw_Data!N12 -> 4 | L12: =Raw_Data!O12 -> 3 | M12: =6-Raw_Data!P12 -> 1 | N12: =Raw_Data!Q12 -> 4 | O12: =Raw_Data!R12 -> 3 | P12: =Raw_Data!S12 -> 5 | Q12: =Raw_Data!T12 -> 5 | R12: =6-Raw_Data!U12 -> 1 | S12: =Raw_Data!V12 -> 3 | T12: =Raw_Data!W12 -> 3 | U12: =Raw_Data!X12 -> 2 | V12: =6-Raw_Data!Y12 -> 3 | W12: =Raw_Data!Z12 -> 5 | X12: =Raw_Data!AA12 -> 5 | Y12: =Raw_Data!AB12 -> 5 | Z12: =Raw_Data!AC12 -> 5 | AA12: =Raw_Data!AD12 -> 3 | AB12: =Raw_Data!AE12 -> 3 | AC12: =6-Raw_Data!AF12 -> 2 | AD12: =Raw_Data!AG12 -> 3 | AE12: =Raw_Data!AH12 -> 4 | AF12: =Raw_Data!AI12 -> 3 | AG12: =Raw_Data!AJ12 -> 5 | AH12: =6-Raw_Data!AK12 -> 1 | AI12: =Raw_Data!AL12 -> 5 | AJ12: =Raw_Data!AM12 -> 5 | AK12: =Raw_Data!AN12 -> 4 | AL12: =6-Raw_Data!AO12 -> 4 | AM12: =Raw_Data!AP12 -> 3 | AN12: =Raw_Data!AQ12 -> 2 | AO12: =Raw_Data!AR12 -> 4 | AP12: =6-Raw_Data!AS12 -> 2 | AQ12: =AVERAGE(Raw_Data!K12,Raw_Data!L12,Raw_Data!M12,Raw_Data!N12,Raw_Data!O12,(6-Raw_Data!P12)) -> 3.3333333 | AR12: =AVERAGE(Raw_Data!Q12,Raw_Data!R12,Raw_Data!S12,Raw_Data!T12,(6-Raw_Data!U12)) -> 3.6 | AS12: =AVERAGE(Raw_Data!V12,Raw_Data!W12,Raw_Data!X12,(6-Raw_Data!Y12)) -> 2.75 | AT12: =AVERAGE(Raw_Data!V12,Raw_Data!X12) -> 2.5 | AU12: =AVERAGE(Raw_Data!Z12,Raw_Data!AA12,Raw_Data!AB12,Raw_Data!AC12,Raw_Data!AD12,Raw_Data!AE12,(6-Raw_Data!AF12)) -> 4 | AV12: =AVERAGE(Raw_Data!AG12,Raw_Data!AH12,Raw_Data!AI12,Raw_Data!AJ12,(6-Raw_Data!AK12)) -> 3.2 | AW12: =AVERAGE(Raw_Data!AL12,Raw_Data!AM12,Raw_Data!AN12,(6-Raw_Data!AO12)) -> 4.5 | AX12: =AVERAGE(Raw_Data!AP12,Raw_Data!AQ12,Raw_Data!AR12,(6-Raw_Data!AS12)) -> 2.75 | AY12: =Raw_Data!BH12 -> 0 | AZ12: =Raw_Data!BI12 -> 0 | BA12: =Raw_Data!BJ12 -> 1 | BB12: =Raw_Data!BK12 -> 0 | BC12: =Raw_Data!BL12 -> 0 | BD12: =Raw_Data!BM12 -> 0 | BE12: =Raw_Data!AU12 -> Exploring — we are evaluating or piloting specific AI tools | BF12: =Raw_Data!AV12 -> Insufficient financial resources | BG12: =Raw_Data!AW12 -> Staff training and professional development | BH12: =Raw_Data!AX12 -> 9 | BI12: =Raw_Data!AZ12 -> More than 50 years | BJ12: =Raw_Data!BA12 -> I am aware of AI tools (e.g., ChatGPT, adaptive learning platforms) but have not used them | BK12: =Raw_Data!BB12 -> Yes — meaningful support from an NGO, private company, or international organisation | BL12: =Raw_Data!BC12 -> I am aware of it and have read parts of it | BM12: =Raw_Data!BD12 -> All of the above — a comprehensive national AI-in-education strategy is needed | BN12: =Raw_Data!BE12 -> Support from an NGO or international development organisation | BO12: =Raw_Data!BF12 -> AI will be integrated into several teaching and administrative functions | BP12: =Raw_Data!BG12 -> The widening gap between well-resourced and under-resourced institutions
A13: =Raw_Data!A13 -> 12 | B13: =Raw_Data!C13 -> Staff | C13: =Raw_Data!D13 -> Senior High School (SHS) | D13: =Raw_Data!G13 -> 1,000 – 4,999 | E13: =Raw_Data!H13 -> 50 – 99 | F13: =Raw_Data!I13 -> Yes, with dedicated full-time staff | G13: =Raw_Data!J13 -> 4 – 7 years | H13: =Raw_Data!K13 -> 5 | I13: =Raw_Data!L13 -> 5 | J13: =Raw_Data!M13 -> 4 | K13: =Raw_Data!N13 -> 4 | L13: =Raw_Data!O13 -> 5 | M13: =6-Raw_Data!P13 -> 5 | N13: =Raw_Data!Q13 -> 4 | O13: =Raw_Data!R13 -> 3 | P13: =Raw_Data!S13 -> 4 | Q13: =Raw_Data!T13 -> 4 | R13: =6-Raw_Data!U13 -> 4 | S13: =Raw_Data!V13 -> 4 | T13: =Raw_Data!W13 -> 5 | U13: =Raw_Data!X13 -> 3 | V13: =6-Raw_Data!Y13 -> 4 | W13: =Raw_Data!Z13 -> 4 | X13: =Raw_Data!AA13 -> 4 | Y13: =Raw_Data!AB13 -> 3 | Z13: =Raw_Data!AC13 -> 3 | AA13: =Raw_Data!AD13 -> 4 | AB13: =Raw_Data!AE13 -> 3 | AC13: =6-Raw_Data!AF13 -> 4 | AD13: =Raw_Data!AG13 -> 4 | AE13: =Raw_Data!AH13 -> 5 | AF13: =Raw_Data!AI13 -> 4 | AG13: =Raw_Data!AJ13 -> 3 | AH13: =6-Raw_Data!AK13 -> 4 | AI13: =Raw_Data!AL13 -> 4 | AJ13: =Raw_Data!AM13 -> 4 | AK13: =Raw_Data!AN13 -> 4 | AL13: =6-Raw_Data!AO13 -> 4 | AM13: =Raw_Data!AP13 -> 3 | AN13: =Raw_Data!AQ13 -> 2 | AO13: =Raw_Data!AR13 -> 3 | AP13: =6-Raw_Data!AS13 -> 2 | AQ13: =AVERAGE(Raw_Data!K13,Raw_Data!L13,Raw_Data!M13,Raw_Data!N13,Raw_Data!O13,(6-Raw_Data!P13)) -> 4.6666667 | AR13: =AVERAGE(Raw_Data!Q13,Raw_Data!R13,Raw_Data!S13,Raw_Data!T13,(6-Raw_Data!U13)) -> 3.8 | AS13: =AVERAGE(Raw_Data!V13,Raw_Data!W13,Raw_Data!X13,(6-Raw_Data!Y13)) -> 4 | AT13: =AVERAGE(Raw_Data!V13,Raw_Data!X13) -> 3.5 | AU13: =AVERAGE(Raw_Data!Z13,Raw_Data!AA13,Raw_Data!AB13,Raw_Data!AC13,Raw_Data!AD13,Raw_Data!AE13,(6-Raw_Data!AF13)) -> 3.5714286 | AV13: =AVERAGE(Raw_Data!AG13,Raw_Data!AH13,Raw_Data!AI13,Raw_Data!AJ13,(6-Raw_Data!AK13)) -> 4 | AW13: =AVERAGE(Raw_Data!AL13,Raw_Data!AM13,Raw_Data!AN13,(6-Raw_Data!AO13)) -> 4 | AX13: =AVERAGE(Raw_Data!AP13,Raw_Data!AQ13,Raw_Data!AR13,(6-Raw_Data!AS13)) -> 2.5 | AY13: =Raw_Data!BH13 -> 1 | AZ13: =Raw_Data!BI13 -> 1 | BA13: =Raw_Data!BJ13 -> 1 | BB13: =Raw_Data!BK13 -> 1 | BC13: =Raw_Data!BL13 -> 1 | BD13: =Raw_Data!BM13 -> 1 | BE13: =Raw_Data!AU13 -> Exploring — we are evaluating or piloting specific AI tools | BF13: =Raw_Data!AV13 -> Insufficient financial resources | BG13: =Raw_Data!AW13 -> Staff training and professional development | BH13: =Raw_Data!AX13 -> 7 | BI13: =Raw_Data!AZ13 -> More than 50 years | BJ13: =Raw_Data!BA13 -> I am aware of AI tools (e.g., ChatGPT, adaptive learning platforms) but have not used them | BK13: =Raw_Data!BB13 -> Some — infrastructure improvement (e.g., internet, devices) through a government programme | BL13: =Raw_Data!BC13 -> I am aware of it and have read parts of it | BM13: =Raw_Data!BD13 -> Fund infrastructure upgrades (internet, devices, electricity) directly | BN13: =Raw_Data!BE13 -> Support from an NGO or international development organisation | BO13: =Raw_Data!BF13 -> AI will be integrated into several teaching and administrative functions | BP13: =Raw_Data!BG13 -> The digital skills gap among students, not just staff
